Workbook

Sheet Summary
A1: D Sculpt Fitness — Production Test Run
A3: Tester | E3: How to use
A4: Date started
A5: Build / URL tested | E5: 1. Work through the "Test Runs" tab top to bottom.
A6: Finance All-Time revenue BEFORE testing | E6: 2. Set Result to Pass / Fail / Blocked / Not tested (dropdown).
A7: Finance All-Time revenue AFTER cleanup | E7: 3. On a Fail, write the ACTUAL numbers you saw in "Actual / notes" —
A8: Member count BEFORE / AFTER | E8: not "wrong", but "Finance showed Rs 7,500, expected Rs 5,000".
E9: 4. Set Severity on every Fail.
A10: Results | E10: 5. Money wrong, two screens disagreeing, or a member seeing data
A11: Total tests | B11: =COUNTA('Test Runs'!A2:A196)-COUNTBLANK('Test Runs'!C2:C196) -> 176 | E11: that is not theirs = Major at minimum.
A12: Pass | B12: =COUNTIF('Test Runs'!F2:F196,"Pass") -> 0 | E12: 6. Screenshot every failure, including the browser console (F12).
A13: Fail | B13: =COUNTIF('Test Runs'!F2:F196,"Fail") -> 0 | E13: 7. Prefix all test data with ZZTEST- and delete it at the end (section 18).
A14: Blocked | B14: =COUNTIF('Test Runs'!F2:F196,"Blocked") -> 0
A15: Not tested | B15: =COUNTIF('Test Runs'!F2:F196,"Not tested") -> 0
A16: Blockers | B16: =COUNTIF('Test Runs'!H2:H196,"Blocker") -> 0
A17: Majors | B17: =COUNTIF('Test Runs'!H2:H196,"Major") -> 0
A18: Minors | B18: =COUNTIF('Test Runs'!H2:H196,"Minor") -> 0
A21: By area — failures
A22: Area | B22: Fail | C22: Blocker+Major
A23: 0 | B23: =COUNTIFS('Test Runs'!B2:B196,A23,'Test Runs'!F2:F196,"Fail") -> 0 | C23: =COUNTIFS('Test Runs'!B2:B196,A23,'Test Runs'!H2:H196,"Blocker")+COUNTIFS('Test Runs'!B2:B196,A23,'Test Runs'!H2:H196,"Major") -> 0
A24: 1 | B24: =COUNTIFS('Test Runs'!B2:B196,A24,'Test Runs'!F2:F196,"Fail") -> 0 | C24: =COUNTIFS('Test Runs'!B2:B196,A24,'Test Runs'!H2:H196,"Blocker")+COUNTIFS('Test Runs'!B2:B196,A24,'Test Runs'!H2:H196,"Major") -> 0
A25: 2 | B25: =COUNTIFS('Test Runs'!B2:B196,A25,'Test Runs'!F2:F196,"Fail") -> 0 | C25: =COUNTIFS('Test Runs'!B2:B196,A25,'Test Runs'!H2:H196,"Blocker")+COUNTIFS('Test Runs'!B2:B196,A25,'Test Runs'!H2:H196,"Major") -> 0
A26: 3 | B26: =COUNTIFS('Test Runs'!B2:B196,A26,'Test Runs'!F2:F196,"Fail") -> 0 | C26: =COUNTIFS('Test Runs'!B2:B196,A26,'Test Runs'!H2:H196,"Blocker")+COUNTIFS('Test Runs'!B2:B196,A26,'Test Runs'!H2:H196,"Major") -> 0
A27: 4 | B27: =COUNTIFS('Test Runs'!B2:B196,A27,'Test Runs'!F2:F196,"Fail") -> 0 | C27: =COUNTIFS('Test Runs'!B2:B196,A27,'Test Runs'!H2:H196,"Blocker")+COUNTIFS('Test Runs'!B2:B196,A27,'Test Runs'!H2:H196,"Major") -> 0
A28: 5 | B28: =COUNTIFS('Test Runs'!B2:B196,A28,'Test Runs'!F2:F196,"Fail") -> 0 | C28: =COUNTIFS('Test Runs'!B2:B196,A28,'Test Runs'!H2:H196,"Blocker")+COUNTIFS('Test Runs'!B2:B196,A28,'Test Runs'!H2:H196,"Major") -> 0
A29: 6 | B29: =COUNTIFS('Test Runs'!B2:B196,A29,'Test Runs'!F2:F196,"Fail") -> 0 | C29: =COUNTIFS('Test Runs'!B2:B196,A29,'Test Runs'!H2:H196,"Blocker")+COUNTIFS('Test Runs'!B2:B196,A29,'Test Runs'!H2:H196,"Major") -> 0
A30: 7 | B30: =COUNTIFS('Test Runs'!B2:B196,A30,'Test Runs'!F2:F196,"Fail") -> 0 | C30: =COUNTIFS('Test Runs'!B2:B196,A30,'Test Runs'!H2:H196,"Blocker")+COUNTIFS('Test Runs'!B2:B196,A30,'Test Runs'!H2:H196,"Major") -> 0
A31: 8 | B31: =COUNTIFS('Test Runs'!B2:B196,A31,'Test Runs'!F2:F196,"Fail") -> 0 | C31: =COUNTIFS('Test Runs'!B2:B196,A31,'Test Runs'!H2:H196,"Blocker")+COUNTIFS('Test Runs'!B2:B196,A31,'Test Runs'!H2:H196,"Major") -> 0
A32: 9 | B32: =COUNTIFS('Test Runs'!B2:B196,A32,'Test Runs'!F2:F196,"Fail") -> 0 | C32: =COUNTIFS('Test Runs'!B2:B196,A32,'Test Runs'!H2:H196,"Blocker")+COUNTIFS('Test Runs'!B2:B196,A32,'Test Runs'!H2:H196,"Major") -> 0
A33: 10 | B33: =COUNTIFS('Test Runs'!B2:B196,A33,'Test Runs'!F2:F196,"Fail") -> 0 | C33: =COUNTIFS('Test Runs'!B2:B196,A33,'Test Runs'!H2:H196,"Blocker")+COUNTIFS('Test Runs'!B2:B196,A33,'Test Runs'!H2:H196,"Major") -> 0
A34: 11 | B34: =COUNTIFS('Test Runs'!B2:B196,A34,'Test Runs'!F2:F196,"Fail") -> 0 | C34: =COUNTIFS('Test Runs'!B2:B196,A34,'Test Runs'!H2:H196,"Blocker")+COUNTIFS('Test Runs'!B2:B196,A34,'Test Runs'!H2:H196,"Major") -> 0
A35: 12 | B35: =COUNTIFS('Test Runs'!B2:B196,A35,'Test Runs'!F2:F196,"Fail") -> 0 | C35: =COUNTIFS('Test Runs'!B2:B196,A35,'Test Runs'!H2:H196,"Blocker")+COUNTIFS('Test Runs'!B2:B196,A35,'Test Runs'!H2:H196,"Major") -> 0
A36: 13 | B36: =COUNTIFS('Test Runs'!B2:B196,A36,'Test Runs'!F2:F196,"Fail") -> 0 | C36: =COUNTIFS('Test Runs'!B2:B196,A36,'Test Runs'!H2:H196,"Blocker")+COUNTIFS('Test Runs'!B2:B196,A36,'Test Runs'!H2:H196,"Major") -> 0
A37: 14 | B37: =COUNTIFS('Test Runs'!B2:B196,A37,'Test Runs'!F2:F196,"Fail") -> 0 | C37: =COUNTIFS('Test Runs'!B2:B196,A37,'Test Runs'!H2:H196,"Blocker")+COUNTIFS('Test Runs'!B2:B196,A37,'Test Runs'!H2:H196,"Major") -> 0
A38: 15 | B38: =COUNTIFS('Test Runs'!B2:B196,A38,'Test Runs'!F2:F196,"Fail") -> 0 | C38: =COUNTIFS('Test Runs'!B2:B196,A38,'Test Runs'!H2:H196,"Blocker")+COUNTIFS('Test Runs'!B2:B196,A38,'Test Runs'!H2:H196,"Major") -> 0
A39: 16 | B39: =COUNTIFS('Test Runs'!B2:B196,A39,'Test Runs'!F2:F196,"Fail") -> 0 | C39: =COUNTIFS('Test Runs'!B2:B196,A39,'Test Runs'!H2:H196,"Blocker")+COUNTIFS('Test Runs'!B2:B196,A39,'Test Runs'!H2:H196,"Major") -> 0
A40: 17 | B40: =COUNTIFS('Test Runs'!B2:B196,A40,'Test Runs'!F2:F196,"Fail") -> 0 | C40: =COUNTIFS('Test Runs'!B2:B196,A40,'Test Runs'!H2:H196,"Blocker")+COUNTIFS('Test Runs'!B2:B196,A40,'Test Runs'!H2:H196,"Major") -> 0
A41: 18 | B41: =COUNTIFS('Test Runs'!B2:B196,A41,'Test Runs'!F2:F196,"Fail") -> 0 | C41: =COUNTIFS('Test Runs'!B2:B196,A41,'Test Runs'!H2:H196,"Blocker")+COUNTIFS('Test Runs'!B2:B196,A41,'Test Runs'!H2:H196,"Major") -> 0

Sheet Test Runs
A1: ID | B1: Area | C1: What to do | D1: What must happen | E1: Why it matters | F1: Result | G1: Actual / notes | H1: Severity | I1: Tester | J1: Date
A2: 0 · Before you start — environment sanity
A3: 0.1 | B3: 0 | C3: Open the production URL in a fresh incognito window | D3: Landing page loads, no console errors, logo and photos render
A4: 0.2 | B4: 0 | C4: Hard-refresh the dashboard 3 times in a row | D4: Never lands on the landing page or a blank screen. (A router race used to do exactly this)
A5: 0.3 | B5: 0 | C5: Open the app, then go offline (airplane mode), then click around | D5: Clear "offline" messaging, not a white screen or a silent failure
A6: 0.4 | B6: 0 | C6: Check the browser console on every page you visit today | D6: Zero red errors. Note any that appear
A7: 0.5 | B7: 0 | C7: Install as a PWA (Add to Home Screen) and open it | D7: Opens standalone, icon correct, works
A8: 0.6 | B8: 0 | C8: Log in, log out, log in again | D8: Second login works without clearing cache
A9: 1 · Member login (member portal)
A10: 1.1 | B10: 1 | C10: Add a brand-new member as owner. **Write down the application number shown.** | D10: The application number is shown clearly after saving and is not blank/`—`/`null` | E10: Members were being created with no application number at all, so they could never log in and nobody knew
A11: 1.2 | B11: 1 | C11: Log in to the member portal with that number + phone | D11: Lands on the member portal
A12: 1.3 | B12: 1 | C12: Log in as a member who was created **weeks ago**, not today | D12: Works too | E12: Old members and new members go through different code paths
A13: 1.4 | B13: 1 | C13: Type the phone **with +91**, with spaces, with a leading 0 | D13: All three work | E13: People paste from Contacts
A14: 1.5 | B14: 1 | C14: Type the application number in lowercase | D14: Works
A15: 1.6 | B15: 1 | C15: Wrong application number, correct phone | D15: Generic error. Must **not** say which field was wrong | E15: Saying "phone is wrong" tells an attacker the number is real
A16: 1.7 | B16: 1 | C16: Correct application number, wrong phone | D16: **Exactly the same** error text as 1.6 | E16: Any difference is a security hole
A17: 1.8 | B17: 1 | C17: Fail login 6 times in a row | D17: Locks out with a "too many attempts" message
A18: 1.9 | B18: 1 | C18: After lockout, wait it out and log in correctly | D18: Works again — you are not locked out permanently
A19: 1.10 | B19: 1 | C19: **Edit that member** (change anything — name, notes, photo) and save. Then log in as them again | D19: Login still works | E19: Editing a member has previously overwritten the application number with blank and silently locked them out. This is the single highest-value test on this page
A20: 1.11 | B20: 1 | C20: Regenerate a member's application number, then try the **old** number | D20: Old number rejected, new number works
A21: 1.12 | B21: 1 | C21: Log in as member A, then log out and log in as member B on the same device | D21: B sees only B's data. No trace of A's name, plan, receipts or visits anywhere
A22: 1.13 | B22: 1 | C22: While logged in as a member, look for anything owner-only: the Add Member button, sidebar, finance figures | D22: Nothing owner-only visible. The floating "+" button in particular has leaked into the member portal before
A23: 1.14 | B23: 1 | C23: Member portal → all four tabs (Check In, My Plan, Receipts, Visits) | D23: All render, nothing blank, no console errors
A24: 1.15 | B24: 1 | C24: Log in as a member whose membership is **expired** | D24: Shows "expired X days ago" — never a negative number like "-5 days remaining" | E24: Fixed once; check both the My Plan tab and the Check In tab, they were separate bugs
A25: 2 · Add member → the money must appear everywhere
A26: 2.1 | B26: 2 | C26: Add `ZZTEST-A` on a ₹2,500 plan, fully paid, Cash | D26: Saves, success message, application number shown
A27: 2.2 | B27: 2 | C27: Members list | D27: Appears, correct plan, correct status, correct expiry
A28: 2.3 | B28: 2 | C28: Finance → This Month | D28: Revenue went up by **exactly ₹2,500**. Cash total went up by ₹2,500. Card and Online unchanged
A29: 2.4 | B29: 2 | C29: Overview | D29: Revenue figure matches Finance. Member count went up by 1
A30: 2.5 | B30: 2 | C30: Open the member → payment history | D30: One payment, ₹2,500, Cash, today's date
A31: 2.6 | B31: 2 | C31: Generate the invoice | D31: Amount ₹2,500, correct name, correct gym details, correct GST treatment
A32: 2.7 | B32: 2 | C32: Hard-refresh, re-check Finance and Overview | D32: Same numbers. Nothing drifted
A33: 2.8 | B33: 2 | C33: Plan **+ an add-on** (e.g. ₹2,500 plan + ₹300 cardio) | D33: Member detail modal must show ₹2,500 plan / ₹300 add-on / **₹2,800 total** — not ₹2,800 plan and ₹3,100 total. Add-ons were being counted twice in the modal while the invoice and DB were correct
A34: 2.9 | B34: 2 | C34: **Partial payment** — ₹2,500 plan, ₹1,000 paid now | D34: Finance revenue +₹1,000 (not ₹2,500). Pending Dues +₹1,500. Member status "Partial". Alerts → Due shows them
A35: 2.10 | B35: 2 | C35: **Zero paid / full due** | D35: Revenue unchanged. Dues +₹2,500
A36: 2.11 | B36: 2 | C36: **With a discount** | D36: Invoice, member modal and Finance all agree on the discounted figure
A37: 2.12 | B37: 2 | C37: **Trial member** | D37: Expiry is the trial date you set, not a plan-derived date. Doesn't pollute revenue if unpaid
... A44: 2.19 | B44: 2 | C44: Name with an apostrophe (`ZZTEST-O'Brien`) and one with `<b>bold</b>` in it | D44: Displays literally. No broken layout, no bold text rendering, no crash. Check the list, the modal, the invoice and the CSV export
A45: 3 · Delete / remove a member
A46: 3.1 | B46: 3 | C46: Add `ZZTEST-B` with a ₹2,000 payment. Note Finance revenue
...
